Workbook

Sheet Sheet1
A1: External ID | B1: Employee Name | C1: NIP | D1: Branch | E1: - | F1: Work Email | I1: Job Position | J1: Tags | K1: Skip-Coach | L1: Skip-Manager | M1: Working start date | N1: Working end date | O1: No. NPWP | P1: No. Kontrak | Q1: Work Address | R1: Private Street | S1: Private Street2 | T1: Private State | U1: Private City | V1: Private Zip | W1: Private Country | X1: Private Email | Y1: Marital Status | AA1: Identification No | AB1: Passport No | AC1: Gender | AD1: Date of Birth | AE1: Create user? | AF1: Nomor Rekening | AG1: Nama Pemilik Rekening | AH1: Bank | AI1: Area | AJ1: Work Phone | AK1: Work Mobile
A2: ="tw_hr_employee_"&C2 -> tw_hr_employee_DWN2412067 | B2: HADIAH KASIM | C2: DWN2412067 | D2: DWN | E2: Cabang Gorontalo | I2: SALESMAN PARTNER | K2: RYAN HIDAYATULLAH ABDILLAH MOITO | M2: 45645 | Q2: PT Tunas Dwipa Matra | W2: Indonesia | X2: hadiahkasim@gmail.com | Y2: Single | AA2: 7102014707720001 | AE2: TRUE | AF2: 523601014649537 | AG2: HADIAH KASIM | AH2: BRI | AI2: =TRIM(IFERROR(VLOOKUP(E2,Mapping!$A$1:$B$2,2,FALSE),E2)) -> Cabang Gorontalo | AJ2: =IF(LEN(G2)>8,G2&"","") | AK2: =IF(LEN(H2)>8,H2&"","")
A3: ="tw_hr_employee_"&C3 -> tw_hr_employee_DWN2402067 | B3: RION MANTULANGI | C3: DWN2402067 | D3: DWN | E3: Cabang Gorontalo | F3: Rionmantulangi@gmail.com | I3: SALESMAN PARTNER | K3: SUWARDI DUNGGIO | M3: 45334 | Q3: PT Tunas Dwipa Matra | W3: Indonesia | X3: Rionmantulangi@gmail.com | Y3: Single | AA3: 7505042602000001 | AE3: TRUE | AF3: 515001011879535 | AG3: RION MANTULANGI | AH3: BRI | AI3: =TRIM(IFERROR(VLOOKUP(E3,Mapping!$A$1:$B$2,2,FALSE),E3)) -> Cabang Gorontalo | AJ3: =IF(LEN(G3)>8,G3&"","") | AK3: =IF(LEN(H3)>8,H3&"","")
A4: ="tw_hr_employee_"&C4 -> tw_hr_employee_DXS2104001 | B4: KRISTINA SOLLENG | C4: DXS2104001 | D4: DXS | E4: Cabang Samarinda | I4: SALES COUNTER PARTNER | K4: EKO WIDODO | M4: 44287 | Q4: PT Tunas Dwipa Matra | R4: JALAN PASUNDAN | S4: JALAN PASUNDAN | T4: 6400 | U4: KOTA SAMARINDA | V4: 75122 | W4: Indonesia | X4: tinak2135@gmail.com | Y4: Single | AA4: 6472034312860003 | AD4: 31749 | AE4: TRUE | AF4: 5135151375 | AG4: KRISTINA SOLLENG | AH4: BCA | AI4: =TRIM(IFERROR(VLOOKUP(E4,Mapping!$A$1:$B$2,2,FALSE),E4)) -> Cabang Samarinda | AJ4: =IF(LEN(G4)>8,G4&"","") | AK4: =IF(LEN(H4)>8,H4&"","")
A5: ="tw_hr_employee_"&C5 -> tw_hr_employee_DWK2402003 | B5: ROMI HIDAYAT RIDAYS | C5: DWK2402003 | D5: DWK | E5: Cabang Kendari | F5: hromi1837@gmail.com | G5: 6285255104890 | I5: SALESMAN PARTNER | K5: ANDI MAKMUR TONGASA | M5: 45324 | Q5: PT Tunas Dwipa Matra | W5: Indonesia | X5: hromi1837@gmail.com | Y5: Single | AA5: 7471040107950010 | AE5: TRUE | AF5: 7911570126 | AG5: ROMI HIDAYAT RIDAYS | AH5: BCA | AI5: =TRIM(IFERROR(VLOOKUP(E5,Mapping!$A$1:$B$2,2,FALSE),E5)) -> Cabang Kendari | AJ5: =IF(LEN(G5)>8,G5&"","") -> 6285255104890 | AK5: =IF(LEN(H5)>8,H5&"","")
A6: ="tw_hr_employee_"&C6 -> tw_hr_employee_DMP2402133 | B6: MUHAMMAD AFIF MUYASSAR | C6: DMP2402133 | D6: DMP | E6: Pramuka | F6: tdmmotor.pramuka@gmail.com | G6: 6281995791375 | I6: SALESMAN PARTNER | K6: RAYNALLDO DELOUIS SAMBUAGA | L6: APRI YANTO | M6: 45334 | Q6: PT Tunas Dwipa Matra | T6: 1800 | U6: KAB. WAY KANAN | V6: 34767 | W6: Indonesia | X6: muhmmadafifmuyassar@gmail.com | Y6: Single | Z6: Indonesia | AA6: 1808090312030001 | AC6: Male | AD6: 37958 | AE6: TRUE | AF6: 2920954637 | AG6: MUHAMMAD AFIF MUYASSAR | AH6: BCA | AI6: =TRIM(IFERROR(VLOOKUP(E6,Mapping!$A$1:$B$2,2,FALSE),E6)) -> Cabang Pramuka | AJ6: =IF(LEN(G6)>8,G6&"","") -> 6281995791375 | AK6: =IF(LEN(H6)>8,H6&"","")
A7: ="tw_hr_employee_"&C7 -> tw_hr_employee_DDA2410001 | B7: MUHIDIN | C7: DDA2410001 | D7: DDA | E7: Cabang Caman | F7: moehidin2021@gmail.com | G7: 6281295772418 | I7: SALESMAN PARTNER | K7: YUNI BUDIANTO | L7: ANFAUZI | M7: 45565 | O7: 240100503045000 | Q7: PT Tunas Dwipa Matra | R7: jl.muncang blok ngg.III/I | T7: 3100 | U7: KOTA JAKARTA UTARA | V7: 14270 | W7: Indonesia | X7: moehidin2021@gmail.com | Y7: Divorced | AA7: 3175062303020001 | AC7: Male | AD7: 27153 | AE7: TRUE | AF7: 4140279787 | AG7: MUHIDIN | AH7: BCA | AI7: =TRIM(IFERROR(VLOOKUP(E7,Mapping!$A$1:$B$2,2,FALSE),E7)) -> Cabang Caman | AJ7: =IF(LEN(G7)>8,G7&"","") -> 6281295772418 | AK7: =IF(LEN(H7)>8,H7&"","")
A8: ="tw_hr_employee_"&C8 -> tw_hr_employee_DDS2401068 | B8: YUSMIATI DEWI | C8: DDS2401068 | D8: DDS | E8: Cabang Saharjo | F8: sausanumamseroja@gmail.com | G8: 6282124929924 | H8: 6282124929924 | I8: SALESMAN PARTNER | K8: YOGI AMRULLAH | L8: YOGI AMRULLAH | M8: 45308 | Q8: PT Tunas Dwipa Matra | W8: Indonesia | X8: sausanumamseroja@gmail.com | Y8: Single | AA8: 3276046008760007 | AE8: TRUE | AF8: 2860576638 | AG8: YUSMIATI DEWI | AH8: BCA | AI8: =TRIM(IFERROR(VLOOKUP(E8,Mapping!$A$1:$B$2,2,FALSE),E8)) -> Cabang Saharjo | AJ8: =IF(LEN(G8)>8,G8&"","") -> 6282124929924 | AK8: =IF(LEN(H8)>8,H8&"","") -> 6282124929924
A9: ="tw_hr_employee_"&C9 -> tw_hr_employee_DXS2503001 | B9: NURMILAH | C9: DXS2503001 | D9: DXS | E9: Cabang Samarinda | F9: 23millamilla@gmail.com | G9: 6281250362800 | I9: SALES COUNTER PARTNER | K9: EKO WIDODO | M9: 45719 | Q9: PT Tunas Dwipa Matra | R9: JL MUSO SALIM GG 7 NO 17 | S9: JL MUSO SALIM GG 7 NO 17 | T9: 6400 | U9: KOTA SAMARINDA | V9: 6472 | W9: Indonesia | X9: 23millamilla@gmail.com | Y9: Single | AA9: 6472036310930007 | AE9: TRUE | AF9: 0272836084 | AG9: NURMILAH | AH9: BCA | AI9: =TRIM(IFERROR(VLOOKUP(E9,Mapping!$A$1:$B$2,2,FALSE),E9)) -> Cabang Samarinda | AJ9: =IF(LEN(G9)>8,G9&"","") -> 6281250362800 | AK9: =IF(LEN(H9)>8,H9&"","")
A10: ="tw_hr_employee_"&C10 -> tw_hr_employee_DWM2404067 | B10: YOSPINA OKKO TARUK | C10: DWM2404067 | D10: DWM | E10: Cabang Tomoni | F10: yospina@gmail.com | I10: SALESMAN PARTNER | K10: LUCKY SETIAWAN | L10: SANDI KALBU KALEMBANG | M10: 45397 | Q10: PT Tunas Dwipa Matra | W10: Indonesia | X10: yospina@gmail.com | Y10: Single | AA10: 7324106310970001 | AE10: TRUE | AF10: 500701021517534 | AG10: YOSPINA OKKO TARUK | AH10: BRI | AI10: =TRIM(IFERROR(VLOOKUP(E10,Mapping!$A$1:$B$2,2,FALSE),E10)) -> Cabang Tomoni | AJ10: =IF(LEN(G10)>8,G10&"","") | AK10: =IF(LEN(H10)>8,H10&"","")
A11: ="tw_hr_employee_"&C11 -> tw_hr_employee_DWN2412068 | B11: YUSMAN PAUS | C11: DWN2412068 | D11: DWN | E11: Cabang Gorontalo | F11: yusmanpaus@gmail.com | I11: SALESMAN PARTNER | K11: RYAN HIDAYATULLAH ABDILLAH MOITO | M11: 45645 | Q11: PT Tunas Dwipa Matra | W11: Indonesia | X11: yusmanpaus@gmail.com | Y11: Single | AA11: 7501041805030001 | AE11: TRUE | AF11: 515901071637539 | AG11: YUSMAN PAUS | AH11: BRI | AI11: =TRIM(IFERROR(VLOOKUP(E11,Mapping!$A$1:$B$2,2,FALSE),E11)) -> Cabang Gorontalo | AJ11: =IF(LEN(G11)>8,G11&"","") | AK11: =IF(LEN(H11)>8,H11&"","")
A12: ="tw_hr_employee_"&C12 -> tw_hr_employee_DWP2410003 | B12: ASNUR AFDIL RAHMATULLAH | C12: DWP2410003 | D12: DWP | E12: Cabang Pinrang | F12: asnur1915@gmail.com | I12: SALESMAN PARTNER | K12: IRWAN ANWAR | M12: 45568 | Q12: PT Tunas Dwipa Matra | W12: Indonesia | X12: asnur1915@gmail.com | Y12: Single | AA12: 7306041603960003 | AE12: TRUE | AF12: 006401014018532 | AG12: ASNUR AFDIL RAHMATULLAH | AH12: BRI | AI12: =TRIM(IFERROR(VLOOKUP(E12,Mapping!$A$1:$B$2,2,FALSE),E12)) -> Cabang Pinrang | AJ12: =IF(LEN(G12)>8,G12&"","") | AK12: =IF(LEN(H12)>8,H12&"","")
A13: ="tw_hr_employee_"&C13 -> tw_hr_employee_DWP2410004 | B13: RISWAN ANWAR | C13: DWP2410004 | D13: DWP | E13: Cabang Pinrang | F13: rizwananwar2580@gmail.com | I13: SALESMAN PARTNER | K13: IRWAN ANWAR | L13: JIHAD ROMADLON MUTTAQIEN | M13: 45568 | Q13: PT Tunas Dwipa Matra | W13: Indonesia | X13: rizwananwar2580@gmail.com | Y13: Single | AA13: 7372040407020001 | AE13: TRUE | AF13: 021801061593506 | AG13: RISWAN ANWAR | AH13: BRI | AI13: =TRIM(IFERROR(VLOOKUP(E13,Mapping!$A$1:$B$2,2,FALSE),E13)) -> Cabang Pinrang | AJ13: =IF(LEN(G13)>8,G13&"","") | AK13: =IF(LEN(H13)>8,H13&"","")
A14: ="tw_hr_employee_"&C14 -> tw_hr_employee_DMP2402134 | B14: NYOMAN RISKI AFANDI | C14: DMP2402134 | D14: DMP | E14: Pramuka | F14: tdmmotor.pramuka@gmail.com | G14: 6281995791375 | I14: SALESMAN PARTNER | K14: RAYNALLDO DELOUIS SAMBUAGA | L14: APRI YANTO | M14: 45334 | Q14: PT Tunas Dwipa Matra | T14: 1800 | U14: KAB. LAMPUNG TENGAH | V14: 34157 | W14: Indonesia | X14: riskiafand@gmail.com | Y14: Single | Z14: Indonesia | AA14: 1802092304910001 | AC14: Male | AD14: 33351 | AE14: TRUE | AF14: 559801011960536 | AG14: NYOMAN RISKI AFANDI | AH14: BRI | AI14: =TRIM(IFERROR(VLOOKUP(E14,Mapping!$A$1:$B$2,2,FALSE),E14)) -> Cabang Pramuka | AJ14: =IF(LEN(G14)>8,G14&"","") -> 6281995791375 | AK14: =IF(LEN(H14)>8,H14&"","")
A15: ="tw_hr_employee_"&C15 -> tw_hr_employee_DLI2412067 | B15: Julianto | C15: DLI2412067 | D15: DLI | E15: Cabang Tanjung Bintang | F15: ZULYWIJAYA@GMAIL.COM | H15: 6285894616028 | I15: SALESMAN PARTNER | K15: Hendi Priadi | L15: FARID ADI SUSILO | M15: 45647 | Q15: PT Tunas Dwipa Matra | R15: BANGUN SARI | T15: 1800 | U15: KAB. LAMPUNG TIMUR | V15: 34376 | W15: Indonesia | X15: ZULYWIJAYA@GMAIL.COM | Y15: Married | AA15: 1807200307900012 | AC15: Male | AD15: 33057 | AE15: TRUE | AF15: 797601004834534 | AG15: Julianto | AH15: BRI | AI15: =TRIM(IFERROR(VLOOKUP(E15,Mapping!$A$1:$B$2,2,FALSE),E15)) -> Cabang Tanjung Bintang | AJ15: =IF(LEN(G15)>8,G15&"","") | AK15: =IF(LEN(H15)>8,H15&"","") -> 6285894616028
A16: ="tw_hr_employee_"&C16 -> tw_hr_employee_DLT2308067 | B16: NURJANAH | C16: DLT2308067 | D16: DLT | E16: Cabang Tulang Bawang | I16: SALESMAN PARTNER | K16: AGUS SUPRIYANTO | M16: 45159 | Q16: PT Tunas Dwipa Matra | R16: PADUAN RAJAWALI | S16: PADUAN RAJAWALI | T16: 1800 | U16: KAB. TULANG BAWANG | V16: 34681 | W16: Indonesia | Y16: Married | Z16: Indonesia | AA16: 1805264609940001 | AC16: Female | AD16: 34583 | AE16: TRUE | AF16: 814201010549531 | AG16: NURJANAH | AH16: BRI | AI16: =TRIM(IFERROR(VLOOKUP(E16,Mapping!$A$1:$B$2,2,FALSE),E16)) -> Cabang Tulang Bawang | AJ16: =IF(LEN(G16)>8,G16&"","") | AK16: =IF(LEN(H16)>8,H16&"","")
A17: ="tw_hr_employee_"&C17 -> tw_hr_employee_DDA2510001 | B17: NASAN | C17: DDA2510001 | D17: DDA | E17: Cabang Caman | F17: bangnasan2015@gmail.com | G17: 6285773303757 | H17: 6285773303757 | I17: SALESMAN PARTNER | K17: MORDANI | L17: ANFAUZI | M17: 45931 | O17: 315944629435000 | Q17: PT Tunas Dwipa Matra | W17: Indonesia | X17: bangnasan2015@gmail.com | Y17: Single | AA17: 3216021606790001 | AE17: TRUE | AF17: 7635102721 | AG17: NASAN | AH17: BCA | AI17: =TRIM(IFERROR(VLOOKUP(E17,Mapping!$A$1:$B$2,2,FALSE),E17)) -> Cabang Caman | AJ17: =IF(LEN(G17)>8,G17&"","") -> 6285773303757 | AK17: =IF(LEN(H17)>8,H17&"","") -> 6285773303757
A18: ="tw_hr_employee_"&C18 -> tw_hr_employee_DDL2403100 | B18: RATU AGUNG MIRAH ANDAYANI | C18: DDL2403100 | D18: DDL | E18: LOMBOK | F18: rmirahandayani@gmail.com | I18: SALESMAN PARTNER | K18: BAMBANG YULIANTO | M18: 45372 | Q18: PT Tunas Dwipa Matra | W18: Indonesia | X18: rmirahandayani@gmail.com | Y18: Single | AA18: 5271064505860001 | AE18: TRUE | AF18: 0561456479 | AG18: RATU AGUNG MIRAH ANDAYANI | AH18: BCA | AI18: =TRIM(IFERROR(VLOOKUP(E18,Mapping!$A$1:$B$2,2,FALSE),E18)) -> Cabang Lombok | AJ18: =IF(LEN(G18)>8,G18&"","") | AK18: =IF(LEN(H18)>8,H18&"","")
A19: ="tw_hr_employee_"&C19 -> tw_hr_employee_DWR2602133 | B19: DESI MONA | C19: DWR2602133 | D19: DWR | E19: Cabang Pare-Pare | F19: Ritapanune77@gmail.com | H19: 6285384846973 | I19: SALESMAN PARTNER | K19: KASMAN | M19: 46071 | Q19: PT Tunas Dwipa Matra | W19: Indonesia | X19: Ritapanune77@gmail.com | Y19: Single | AA19: 1671025512830013 | AE19: TRUE | AF19: 8435343739 | AG19: DESI MONA | AH19: BCA | AI19: =TRIM(IFERROR(VLOOKUP(E19,Mapping!$A$1:$B$2,2,FALSE),E19)) -> Cabang Pare-Pare | AJ19: =IF(LEN(G19)>8,G19&"","") | AK19: =IF(LEN(H19)>8,H19&"","") -> 6285384846973
A20: ="tw_hr_employee_"&C20 -> tw_hr_employee_DDL2509001 | B20: MOHAMMAD ARIEF | C20: DDL2509001 | D20: DDL | E20: LOMBOK | F20: moh.arief1982@gmail.com | I20: SALESMAN PARTNER | K20: BAMBANG YULIANTO | M20: 45902 | Q20: PT Tunas Dwipa Matra | W20: Indonesia | X20: moh.arief1982@gmail.com | Y20: Single | AA20: 5271010604820002 | AE20: TRUE | AF20: 349501031830539 | AG20: MOHAMMAD ARIEF | AH20: BRI | AI20: =TRIM(IFERROR(VLOOKUP(E20,Mapping!$A$1:$B$2,2,FALSE),E20)) -> Cabang Lombok | AJ20: =IF(LEN(G20)>8,G20&"","") | AK20: =IF(LEN(H20)>8,H20&"","")
A21: ="tw_hr_employee_"&C21 -> tw_hr_employee_DDT2401001 | B21: NI LUH JEPUN JULIANTARI | C21: DDT2401001 | D21: DDT | E21: Cabang Tabanan | I21: SALESMAN PARTNER | K21: I GEDE SUKAWIDANA | L21: GILANG RADIKTYA | M21: 45308 | P21: 085739952052 | Q21: PT Tunas Dwipa Matra | R21: BR DINAS KEBON KAJA | T21: 5100 | U21: KAB. TABANAN | V21: 82163 | W21: Indonesia | X21: jepunjuliantari1993@gmail.com | Y21: Single | AA21: 5202014706930001 | AE21: TRUE | AF21: 057001011202503 | AG21: NI LUH JEPUN JULIANTARI | AH21: BRI | AI21: =TRIM(IFERROR(VLOOKUP(E21,Mapping!$A$1:$B$2,2,FALSE),E21)) -> Cabang Tabanan | AJ21: =IF(LEN(G21)>8,G21&"","") | AK21: =IF(LEN(H21)>8,H21&"","")
A22: ="tw_hr_employee_"&C22 -> tw_hr_employee_DLN2308034 | B22: DAYU AISMAWANTO | C22: DLN2308034 | D22: DLN | E22: Cabang Kota Agung | H22: 6285208411284 | I22: SALESMAN PARTNER | K22: DEVIANA RAHMAWATI | M22: 45159 | Q22: PT Tunas Dwipa Matra | W22: Indonesia | X22: dayuaism1@gmail.com | Y22: Single | AA22: 1810030507950002 | AE22: TRUE | AF22: 035801056667506 | AG22: DAYU AISMAWANTO | AH22: BRI | AI22: =TRIM(IFERROR(VLOOKUP(E22,Mapping!$A$1:$B$2,2,FALSE),E22)) -> Cabang Kota Agung | AJ22: =IF(LEN(G22)>8,G22&"","") | AK22: =IF(LEN(H22)>8,H22&"","") -> 6285208411284
A23: ="tw_hr_employee_"&C23 -> tw_hr_employee_DXS2101001 | B23: YULIANA | C23: DXS2101001 | D23: DXS | E23: Cabang Samarinda | I23: SALES COUNTER PARTNER | K23: EKO WIDODO | M23: 44211 | Q23: PT Tunas Dwipa Matra | R23: JL PADAT KARYA GG TANJUNG | S23: JL PADAT KARYA GG TANJUNG | T23: 6400 | U23: KAB. KUTAI KARTANEGARA | V23: 75391 | W23: Indonesia | X23: yulianayun1900@gmail.com | Y23: Married | AA23: 6402034102960003 | AC23: Female | AD23: 35797 | AE23: TRUE | AF23: 8145245997 | AG23: YULIANA | AH23: BCA | AI23: =TRIM(IFERROR(VLOOKUP(E23,Mapping!$A$1:$B$2,2,FALSE),E23)) -> Cabang Samarinda | AJ23: =IF(LEN(G23)>8,G23&"","") | AK23: =IF(LEN(H23)>8,H23&"","")
A24: ="tw_hr_employee_"&C24 -> tw_hr_employee_DLI2402067 | B24: Shindi Firnanda | C24: DLI2402067 | D24: DLI | E24: Cabang Tanjung Bintang | F24: SHINDIFIRNANDA09@GMAIL.COM | I24: SALESMAN PARTNER | K24: DIDIT ADITYA MAHARDDHIKA | L24: DIDIT ADITYA MAHARDDHIKA | M24: 45334 | Q24: PT Tunas Dwipa Matra | R24: Dusun Totoharjo | T24: 1800 | U24: KAB. LAMPUNG SELATAN | V24: 35361 | W24: Indonesia | X24: SHINDIFIRNANDA09@GMAIL.COM | Y24: Single | Z24: Indonesia | AA24: 1801054904040001 | AC24: Female | AD24: 38086 | AE24: TRUE | AF24: 2941093568 | AG24: Shindi Firnanda | AH24: BCA | AI24: =TRIM(IFERROR(VLOOKUP(E24,Mapping!$A$1:$B$2,2,FALSE),E24)) -> Cabang Tanjung Bintang | AJ24: =IF(LEN(G24)>8,G24&"","") | AK24: =IF(LEN(H24)>8,H24&"","")
A25: ="tw_hr_employee_"&C25 -> tw_hr_employee_DJB2407034 | B25: FITRI WAHYUNINGSIH | C25: DJB2407034 | D25: DJB | E25: Cabang Bangko | F25: fitriwahyuningsih889@gmail.com | G25: 6282183254021 | H25: 6282183254021 | I25: SALESMAN PARTNER | K25: PRASTYO WIDODO | L25: VICTOR PRATAMA | M25: 45483 | Q25: PT Tunas Dwipa Matra | W25: Indonesia | X25: fitriwahyuningsih889@gmail.com | Y25: Single | AA25: 1503085208950001 | AE25: TRUE | AF25: 806201010669533 | AG25: FITRI WAHYUNINGSIH | AH25: BRI | AI25: =TRIM(IFERROR(VLOOKUP(E25,Mapping!$A$1:$B$2,2,FALSE),E25)) -> Cabang Bangko | AJ25: =IF(LEN(G25)>8,G25&"","") -> 6282183254021 | AK25: =IF(LEN(H25)>8,H25&"","") -> 6282183254021
A26: ="tw_hr_employee_"&C26 -> tw_hr_employee_DDC2411001 | B26: RIA FARIANSYAH ANGELINA PUTRI | C26: DDC2411001 | D26: DDC | E26: Cabang Cimareme | F26: fariiiansyah63@gmail.com | I26: SALES COUNTER PARTNER | K26: YONGKI SULAIMAN | L26: YONGKI SULAIMAN | M26: 45596 | Q26: PT Tunas Dwipa Matra | R26: JL KERKOF BLOK PADAKASIH | T26: 3200 | U26: KOTA CIMAHI | V26: 40531 | W26: Indonesia | X26: fariiiansyah63@gmail.com | Y26: Single | AA26: 3277014710030007 | AE26: TRUE | AF26: 1393693723 | AG26: RIA FARIANSYAH ANGELINA PUTRI | AH26: BCA | AI26: =TRIM(IFERROR(VLOOKUP(E26,Mapping!$A$1:$B$2,2,FALSE),E26)) -> Cabang Cimareme | AJ26: =IF(LEN(G26)>8,G26&"","") | AK26: =IF(LEN(H26)>8,H26&"","")
A27: ="tw_hr_employee_"&C27 -> tw_hr_employee_DDJ2406067 | B27: YUSTIKA NOVIANTO | C27: DDJ2406067 | D27: DDJ | E27: Cabang Jombang | F27: yustika674@gmail.com | I27: SALESMAN PARTNER | K27: HARI SUNOTO | M27: 45451 | Q27: PT Tunas Dwipa Matra | W27: Indonesia | X27: yustika674@gmail.com | Y27: Single | AA27: 3506144811910003 | AE27: TRUE | AF27: 624901020677538 | AG27: YUSTIKA NOVIANTO | AH27: BRI | AI27: =TRIM(IFERROR(VLOOKUP(E27,Mapping!$A$1:$B$2,2,FALSE),E27)) -> Cabang Jombang | AJ27: =IF(LEN(G27)>8,G27&"","") | AK27: =IF(LEN(H27)>8,H27&"","")
A28: ="tw_hr_employee_"&C28 -> tw_hr_employee_HSMK22001 | B28: REZZA SCONDINAVIA NOOR ARASY | C28: HSMK22001 | D28: DDU | E28: Cabang Sukabumi | F28: rezzaarasy@gmail.com | I28: SALESMAN PARTNER | K28: ANDRI NUGRAHA | M28: 45689 | Q28: PT Tunas Dwipa Matra | R28: KP.CIBUNTU | T28: 3200 | U28: KAB. SUKABUMI | V28: 43192 | W28: Indonesia | X28: rezzaarasy@gmail.com | Y28: Single | AA28: 3272012801860001 | AD28: 31440 | AE28: TRUE | AF28: 3771548596 | AG28: REZZA SCONDINAVIA NOOR ARASY | AH28: BCA | AI28: =TRIM(IFERROR(VLOOKUP(E28,Mapping!$A$1:$B$2,2,FALSE),E28)) -> Cabang Sukabumi | AJ28: =IF(LEN(G28)>8,G28&"","") | AK28: =IF(LEN(H28)>8,H28&"","")
A29: ="tw_hr_employee_"&C29 -> tw_hr_employee_DWK2310067 | B29: MEISYAH PUTRI HARYA | C29: DWK2310067 | D29: DWK | E29: Cabang Kendari | G29: 6281239932359 | I29: SALESMAN PARTNER | K29: MUH SYAFRIE.SE | M29: 45202 | Q29: PT Tunas Dwipa Matra | W29: Indonesia | X29: meisyahputriharya@gmail.com | Y29: Single | AA29: 3175055905971001 | AE29: TRUE | AF29: 019201150707501 | AG29: MEISYAH PUTRI HARYA | AH29: BRI | AI29: =TRIM(IFERROR(VLOOKUP(E29,Mapping!$A$1:$B$2,2,FALSE),E29)) -> Cabang Kendari | AJ29: =IF(LEN(G29)>8,G29&"","") -> 6281239932359 | AK29: =IF(LEN(H29)>8,H29&"","")
A30: ="tw_hr_employee_"&C30 -> tw_hr_employee_DJB2309067 | B30: HALIMATU SA'ADAH | C30: DJB2309067 | D30: DJB | E30: Cabang Bangko | F30: halimatusaadah5@gmail.com | G30: 6282247062853 | H30: 6282247062853 | I30: SALESMAN PARTNER | K30: BUDI SANTOSO | L30: VICTOR PRATAMA | M30: 45176 | Q30: PT Tunas Dwipa Matra | W30: Indonesia | X30: saadahhalimatu9@gmail.com | Y30: Single | AA30: 1502025302000002 | AE30: TRUE | AF30: 6197011540 | AG30: HALIMATU SA'ADAH | AH30: BCA | AI30: =TRIM(IFERROR(VLOOKUP(E30,Mapping!$A$1:$B$2,2,FALSE),E30)) -> Cabang Bangko | AJ30: =IF(LEN(G30)>8,G30&"","") -> 6282247062853 | AK30: =IF(LEN(H30)>8,H30&"","") -> 6282247062853
A31: ="tw_hr_employee_"&C31 -> tw_hr_employee_DMN2509001 | B31: DWI RIYANTO | C31: DMN2509001 | D31: DMN | E31: Cabang Natar | F31: LISAFATIR784@GMAIL.COM | G31: 6282183783660 | H31: 6282183783660 | I31: SALESMAN PARTNER | K31: ROHANDI | M31: 45902 | Q31: PT Tunas Dwipa Matra | R31: Dsn Purwosari Ii | S31: Dsn Purwosari Ii | T31: 1800 | U31: KAB. LAMPUNG SELATAN | V31: 34372 | W31: Indonesia | X31: LISAFATIR784@GMAIL.COM | Y31: Married | AA31: 1803102001870001 | AC31: Male | AD31: 31797 | AE31: TRUE | AF31: 0201433460 | AG31: DWI RIYANTO | AH31: BCA | AI31: =TRIM(IFERROR(VLOOKUP(E31,Mapping!$A$1:$B$2,2,FALSE),E31)) -> Cabang Natar | AJ31: =IF(LEN(G31)>8,G31&"","") -> 6282183783660 | AK31: =IF(LEN(H31)>8,H31&"","") -> 6282183783660
A32: ="tw_hr_employee_"&C32 -> tw_hr_employee_DLA2411001 | B32: RETNO PRATIWI | C32: DLA2411001 | D32: DLA | E32: Cabang Antasari | F32: retnopratiwi070@gmail.com | G32: 6281279475554 | I32: SALESMAN PARTNER | K32: RIVAN LIBRIAN | M32: 45598 | Q32: PT Tunas Dwipa Matra | W32: Indonesia | X32: retnopratiwi070@gmail.com | Y32: Single | AA32: 1871024808940005 | AE32: TRUE | AF32: 0201324351 | AG32: RETNO PRATIWI | AH32: BCA | AI32: =TRIM(IFERROR(VLOOKUP(E32,Mapping!$A$1:$B$2,2,FALSE),E32)) -> Cabang Antasari | AJ32: =IF(LEN(G32)>8,G32&"","") -> 6281279475554 | AK32: =IF(LEN(H32)>8,H32&"","")
A33: ="tw_hr_employee_"&C33 -> tw_hr_employee_DJM2301100 | B33: NOPITA SARI | C33: DJM2301100 | D33: DJM | E33: Cabang Merlung | I33: SALESMAN PARTNER | K33: DJM-MUHAMMAD AMIN RIANDI | L33: RIKOH FERDINAN ARDIANSYAH | M33: 44946 | Q33: PT Tunas Dwipa Matra | R33: JL SATRIA BHAKTI | S33: JL SATRIA BHAKTI | T33: 1500 | U33: KAB. TANJUNG JABUNG BARAT | V33: 12345 | W33: Indonesia | X33: Novitasari29929@gmail.com | Y33: Single | AA33: 1506055712971001 | AC33: Female | AD33: 35781 | AE33: TRUE | AF33: 566701017998532 | AG33: NOPITA SARI | AH33: BRI | AI33: =TRIM(IFERROR(VLOOKUP(E33,Mapping!$A$1:$B$2,2,FALSE),E33)) -> Cabang Merlung | AJ33: =IF(LEN(G33)>8,G33&"","") | AK33: =IF(LEN(H33)>8,H33&"","")
A34: ="tw_hr_employee_"&C34 -> tw_hr_employee_DWK2402034 | B34: IVAN WAHYU HUTAMA | C34: DWK2402034 | D34: DWK | E34: Cabang Kendari | F34: ivanwahyu95@gmail.com | G34: 6285282576758 | I34: SALESMAN PARTNER | M34: 45334 | Q34: PT Tunas Dwipa Matra | W34: Indonesia | X34: ivanwahyu95@gmail.com | Y34: Single | AA34: 7405050111950001 | AE34: TRUE | AF34: 7911209920 | AG34: IVAN WAHYU HUTAMA | AH34: BCA | AI34: =TRIM(IFERROR(VLOOKUP(E34,Mapping!$A$1:$B$2,2,FALSE),E34)) -> Cabang Kendari | AJ34: =IF(LEN(G34)>8,G34&"","") -> 6285282576758 | AK34: =IF(LEN(H34)>8,H34&"","")
A35: ="tw_hr_employee_"&C35 -> tw_hr_employee_DWT2312034 | B35: MOH. FAHKRI BARENG | C35: DWT2312034 | D35: DWT | E35: Cabang Tuminting | I35: SALESMAN PARTNER | K35: YAYAN SUGANDI LOMPAD | L35: TIKNO BABTISO PALANTI | M35: 45265 | Q35: PT Tunas Dwipa Matra | R35: JL. BERINGIN | S35: JL. BERINGIN | T35: 7100 | U35: KOTA KOTAMOBAGU | W35: Indonesia | X35: aibareng051@gmail.com | Y35: Divorced | AA35: 7174041602880001 | AC35: Male | AD35: 32189 | AE35: TRUE | AF35: 003601018568538 | AG35: MOH. FAHKRI BARENG | AH35: BRI | AI35: =TRIM(IFERROR(VLOOKUP(E35,Mapping!$A$1:$B$2,2,FALSE),E35)) -> Cabang Tuminting | AJ35: =IF(LEN(G35)>8,G35&"","") | AK35: =IF(LEN(H35)>8,H35&"","")
A36: ="tw_hr_employee_"&C36 -> tw_hr_employee_DMK2410035 | B36: DWI FITRIA | C36: DMK2410035 | D36: DMK | E36: Cabang Katibung | F36: dwift143@gmail.com | I36: SALESMAN PARTNER | K36: RIZKY KURNIAWAN | M36: 45566 | Q36: PT Tunas Dwipa Matra | W36: Indonesia | X36: dwift143@gmail.com | Y36: Single | AA36: 1609134511050001 | AE36: TRUE | AF36: 060301016769533 | AG36: DWI FITRIA | AH36: BRI | AI36: =TRIM(IFERROR(VLOOKUP(E36,Mapping!$A$1:$B$2,2,FALSE),E36)) -> Cabang Katibung | AJ36: =IF(LEN(G36)>8,G36&"","") | AK36: =IF(LEN(H36)>8,H36&"","")
A37: ="tw_hr_employee_"&C37 -> tw_hr_employee_DDT2409001 | B37: SHEENDY MERCURRY MEGASI | C37: DDT2409001 | D37: DDT | E37: Cabang Tabanan | F37: sheendym@gmail.com | I37: TEAM LEADER PARTNER | K37: ERIS KUSWANTORO | M37: 45538 | Q37: PT Tunas Dwipa Matra | W37: Indonesia | X37: sheendym@gmail.com | Y37: Single | AA37: 3574042704880001 | AE37: TRUE | AF37: 0390607741 | AG37: SHEENDY MERCURRY MEGASI | AH37: BCA | AI37: =TRIM(IFERROR(VLOOKUP(E37,Mapping!$A$1:$B$2,2,FALSE),E37)) -> Cabang Tabanan | AJ37: =IF(LEN(G37)>8,G37&"","") | AK37: =IF(LEN(H37)>8,H37&"","")
A38: ="tw_hr_employee_"&C38 -> tw_hr_employee_DXK2509001 | B38: LEONARDO | C38: DXK2509001 | D38: DXK | E38: Cabang Ketapang | F38: leoxibdp@gmail.com | H38: 62895702218157 | I38: SALESMAN PARTNER | K38: SUARNI | L38: GUNTUR ADYTYA DWI SAPUTRA | M38: 45902 | Q38: PT Tunas Dwipa Matra | W38: Indonesia | X38: leoxibdp@gmail.com | Y38: Single | AA38: 6104162405040001 | AE38: TRUE | AF38: 8955507246 | AG38: LEONARDO | AH38: BCA | AI38: =TRIM(IFERROR(VLOOKUP(E38,Mapping!$A$1:$B$2,2,FALSE),E38)) -> Cabang Ketapang | AJ38: =IF(LEN(G38)>8,G38&"","") | AK38: =IF(LEN(H38)>8,H38&"","") -> 62895702218157
A39: ="tw_hr_employee_"&C39 -> tw_hr_employee_DJM2203001 | B39: JUFRI | C39: DJM2203001 | D39: DJM | E39: Cabang Merlung | I39: SALESMAN PARTNER | K39: HASBULLAH | L39: RIKOH FERDINAN ARDIANSYAH | M39: 44630 | Q39: PT Tunas Dwipa Matra | R39: LUBUK TERAP | S39: LUBUK TERAP | T39: 1500 | U39: KAB. TANJUNG JABUNG BARAT | V39: 36554 | W39: Indonesia | X39: jufrindan501@gmail.com | Y39: Single | AA39: 1506051212950001 | AC39: Male | AD39: 35045 | AE39: TRUE | AF39: 566701013353536 | AG39: JUFRI | AH39: BRI | AI39: =TRIM(IFERROR(VLOOKUP(E39,Mapping!$A$1:$B$2,2,FALSE),E39)) -> Cabang Merlung | AJ39: =IF(LEN(G39)>8,G39&"","") | AK39: =IF(LEN(H39)>8,H39&"","")
A40: ="tw_hr_employee_"&C40 -> tw_hr_employee_DDL2509034 | B40: SAHUDIN | C40: DDL2509034 | D40: DDL | E40: LOMBOK | F40: sahudin193@gmail.com | I40: SALESMAN PARTNER | K40: BAMBANG YULIANTO | M40: 45902 | Q40: PT Tunas Dwipa Matra | W40: Indonesia | X40: sahudin193@gmail.com | Y40: Single | AA40: 5208023112810154 | AE40: TRUE | AF40: 2320767329 | AG40: SAHUDIN | AH40: BCA | AI40: =TRIM(IFERROR(VLOOKUP(E40,Mapping!$A$1:$B$2,2,FALSE),E40)) -> Cabang Lombok | AJ40: =IF(LEN(G40)>8,G40&"","") | AK40: =IF(LEN(H40)>8,H40&"","")
...

Sheet Mapping
A1: Pramuka | B1: Cabang Pramuka
A2: LOMBOK | B2: Cabang Lombok
